Workbook

Sheet ملخص عام
A1: ملخص عام - مؤشرات مكافحة الفساد (2022-2025)
A2: مستخرج من التقارير السنوية للإدارة العامة للتحقيق - هيئة مكافحة الفساد الفلسطينية
A4: # | B4: اسم المؤشر | C4: الحالة (متوفر/غير متوفر)
A5: 1 | B5: عدد التشريعات/البنود المُقرّة أو المعدّلة | C5: غير متوفر
A6: 2 | B6: جودة وفاعلية التشريعات ذات العلاقة بمكافحة الفساد | C6: غير متوفر
A7: 3 | B7: الملفات التحقيقية المحالة حسب القطاع وحسب الجرم | C7: متوفر بالكامل
A8: 4 | B8: عدد الملفات التحقيقية لدى الهيئة (الواردة) | C8: متوفر بالكامل
A9: 5 | B9: عدد الملفات التحقيقية المنجزة | C9: متوفر بالكامل
A10: 6 | B10: عدد القضايا الواردة لنيابة جرائم الفساد | C10: متوفر (كملفات محالة من الهيئة)
A11: 7 | B11: نسبة ملفات التحقيق الجزائي المنجزة لدى النيابة | C11: متوفر (تقريبي/محسوب - راجع التحفظ في شيت 7)
A12: 8 | B12: عدد المتهمين المحالين إلى محكمة جرائم الفساد | C12: متوفر بالكامل (تم تحديثه من نموذج إحصائي إضافي - نموذج رقم 1)
A13: 9 | B13: عدد القضايا المفصولة بحكم في محكمة جرائم الفساد | C13: متوفر بالكامل (تم تحديثه من نموذج إحصائي إضافي - نموذج رقم 2)
A14: 10 | B14: عدد المدانين في القضايا المفصولة بحكم | C14: متوفر بالكامل (تم تحديثه من نموذج إحصائي إضافي - نموذج رقم 2)
A15: 11 | B15: عدد المكلفين بإقرارات الذمة المالية | C15: غير متوفر (عدد الأفراد) - لكن أُضيف عدد "الجهات" المكلفة كمؤشر بديل 11ب
A16: 12 | B16: عدد إقرارات الذمة المالية الموزعة | C16: متوفر بالكامل (تمت تعبئته - عدد النماذج الموزعة/المسلمة)
... A23: 19 | B23: نسبة الأشخاص الذين دفعوا رشوة فعليًا | C23: غير متوفر
A25: مؤشرات إضافية - وتشمل مؤشر 26 الأصلية PDF
A26: # | B26: اسم المؤشر | C26: الحالة
A27: 20 | B27: توزيع الملفات الواردة حسب القطاع | C27: متوفر بالكامل
A28: 21 | B28: تصنيف جرائم الفساد في الملفات الواردة | C28: متوفر بالكامل (تم تصحيح: بيانات 2024 متوفرة فعليًا في الشيت، المجموع 193)
A29: 22 | B29: توزيع الملفات المحفوظة حسب القطاع والجرم | C29: جزئي (2022 فقط بالتفصيل)
A30: 23 | B30: الملفات المحوّلة للنيابة العامة (غير فساد) | C30: متوفر بالكامل
A31: 24 | B31: أعمال الضبط القضائي والتحري والاستدلال | C31: جزئي (2023 و2024 فقط)
A32: 25 | B32: نسب ومعدلات مشتقة (إحالة، حفظ، رد، نمو...) | C32: محسوبة بصيغ Excel من بيانات الأعوام الأربعة
A33: 26 | B33: الملفات المنتهية لوجود ملف مماثل لدى نيابة جرائم الفساد | C33: متوفر بالكامل (مؤشر جديد لم يكن مدرجًا)
A34: 27 | B34: تفصيل الشكاوى الجديدة/الملحقة وتفصيل الملفات والشكاوى المغلقة حسب نوع القرار | C34: جزئي (شكاوى جديدة/ملحقة: 2022 و2023 فقط؛ تفصيل حسب نوع القرار: متوفر بالكامل للأعوام الأربعة)
A35: 28 | B35: الشكاوى والبلاغات الواردة لهيئة مكافحة الفساد حسب مصدر التقديم | C35: متوفر بالكامل (مؤشر جديد من نماذج الشكاوى - مستوى الشكاوى وليس الملفات)
A36: 29 | B36: تصنيف الشكاوى والبلاغات حسب التكييف الأولي لجرم الفساد | C36: جزئي (بدون مجموع مثبت في النموذج الأصلي)
A37: 30 | B37: توزيع الشكاوى والبلاغات حسب القطاع | C37: جزئي (بدون مجموع مثبت في النموذج الأصلي)
A38: 31 | B38: توزيع الشكاوى والبلاغات حسب طريقة الاستلام | C38: متوفر بالكامل (مؤشر جديد)
... A40: 33 | B40: توزيع الشكاوى والبلاغات حسب الدرجة الوظيفية للمشتكى عليه | C40: جزئي (بدون مجموع مثبت في النموذج الأصلي)
A42: ملاحظة: تمت مراجعة ملفات 'نماذج التحقيق' و'نماذج الحماية' و'نماذج الشكاوى' و'نماذج النيابة والمحكمة' كمصادر تكميلية. نماذج 'التحقيق' و'النيابة والمحكمة' لم تتضمن بيانات رقمية إضافية عما هو مثبت مسبقًا (قوالب فارغة أو بيانات مطابقة لعام 2022 فقط)، بينما زوّدت نماذج 'الحماية' و'الشكاوى' ببيانات فعلية جديدة استُخدمت لتحديث المؤشرات 15 و16، وإضافة صفحات تفصيلية جديدة (15ب، 15ج، 28-33).
A43: 34 | B43: ملخص القضايا والمشتبه بهم لدى نيابة جرائم الفساد (نموذج رقم 1) | C43: متوفر بالكامل (مؤشر جديد من نموذج نيابة جرائم الفساد)
A44: 37 | B44: عدد الجهات المكلفة بتقديم إقرارات الذمة المالية (مؤشر جديد 11ب) | C44: متوفر بالكامل (مؤشر جديد)
A45: 38 | B45: عدد الإقرارات الدورية (تجديد كل 5 سنوات) (مؤشر جديد 12ب) | C45: متوفر بالكامل (مؤشر جديد)
A46: 39 | B46: المجموع التراكمي لإقرارات الذمة المالية منذ 2012 (مؤشر جديد 12ج) | C46: متوفر بالكامل (مؤشر جديد)
A47: 40 | B47: التوزيع النسبي التراكمي للإقرارات حسب فئة المكلفين 2012-2024 (مؤشر جديد 12د) | C47: متوفر بالكامل (مؤشر جديد)
A48: 41 | B48: تفصيل فحص إقرارات الذمة المالية حسب السبب والجنس (مؤشر جديد ضمن شيت 14) | C48: متوفر بالكامل (مؤشر جديد - يحتاج مطابقة مع البيانات السابقة)
A50: مؤشرات مضافة حديثاً بعد التدقيق الإضافي (راجع الشيتات 42-46)
A51: 42 | B51: ضبط وإعادة أموال عامة (بالشيكل) | C51: متوفر جزئياً (2022 و2023 فقط - غير موجود في تقريري 2024 و2025)
...

Sheet 1-التشريعات
A1: 1. عدد التشريعات-البنود المُقرّة أو المعدّلة المعزِّزة للوقاية من الفساد | G1: ⬆ رجوع للملخص العام
A2: مجموع أعداد التشريعات/البنود التي تم إقرارها أو تعديلها سنويًا كمعزِّزة للبيئة الطاردة للفساد
A4: البيان | B4: 2022 | C4: 2023 | D4: 2024 | E4: 2025
A5: عدد التشريعات/البنود | B5: 1 | C5: 1 | D5: 0 | E5: 0
A7: ملاحظة: هذا المؤشر غير مرصود في التقارير السنوية المرفقة (تقارير الإدارة العامة للتحقيق)، إذ إن مصدره الرسمي المفترض هو سجلات الهيئة والجريدة الرسمية، وهو غير موضّح ضمن هذه التقارير. الأرقام التي اضفتها تم البحث عنها بالانترنت
I18: 📊 يوضح الرسم البياني أعلاه: 1. عدد التشريعات-البنود المُقرّة أو المعدّلة المعزِّزة للوقاية من الفساد — مقارنة الأرقام عبر الأعوام المتاحة في الجدول المقابل.

Sheet 2-جودة التشريعات
A1: 2. جودة وفاعلية التشريعات ذات العلاقة بمكافحة الفساد | G1: ⬆ رجوع للملخص العام
A2: مؤشر تقييمي عبر استطلاع رأي/مجموعات بؤرية بالتنسيق مع الجهاز المركزي للإحصاء الفلسطيني | I2: 📊 لا يمكن إنشاء رسم بياني لهذا المؤشر لعدم توفر أي بيانات رقمية له في التقارير المرفقة.
A4: البيان | B4: 2022 | C4: 2023 | D4: 2024 | E4: 2025
A5: تقييم/عدد | B5: غير متوفر | C5: غير متوفر | D5: غير متوفر | E5: غير متوفر
A7: ملاحظة: غير متوفر في التقارير المرفقة؛ هذا المؤشر يعتمد على استطلاع رأي مخصص بالتعاون مع الجهاز المركزي للإحصاء الفلسطيني وليس على سجلات الإدارة العامة للتحقيق.

Sheet 3-المحالة حسب القطاع والجرم
A1: 3. مؤشر الملفات التحقيقية المحالة إلى النائب العام حسب القطاع وحسب الجرم | G1: ⬆ رجوع للملخص العام
A2: توزيع الملفات المحالة للنائب العام سنويًا حسب القطاع (الجهة) وحسب نوع التكييف الجرمي
A4: أ) توزيع الملفات المحالة حسب القطاع (الجهة)
A5: القطاع/الجهة | B5: 2022 | C5: 2023 | D5: 2024 | E5: 2025
A6: قطاع عام/وزارات ومؤسسات وزارية | B6: 28 | C6: 10 | D6: 13 | E6: 21
A7: هيئات محلية | B7: 19 | C7: 17 | D7: 20 | E7: 9
A8: جمعيات | B8: 8 | C8: 3 | D8: 1 | E8: 4
A9: اتحادات ونقابات | B9: 2 | C9: 1 | D9: 0 | E9: 2
A10: شركة/شركات مساهمة عامة | B10: 1 | C10: 0 | D10: 0 | E10: 2
A11: خبراء – مخمن عقاري | B11: 1 | C11: 0 | D11: 0 | E11: 0
A12: لجان | B12: 0 | C12: 1 | D12: 0 | E12: 0
A13: مؤسسة عامة | B13: 0 | C13: 0 | D13: 1 | E13: 0
A14: مكلف بخدمة عامة | B14: 0 | C14: 0 | D14: 1 | E14: 0
A15: جمعيات خيرية | B15: 0 | C15: 0 | D15: 1 | E15: 0
A16: حارس قضائي | B16: 0 | C16: 0 | D16: 1 | E16: 0
A17: أندية | B17: 0 | C17: 0 | D17: 0 | E17: 1
A18: مؤسسات منظمة التحرير | B18: 0 | C18: 0 | D18: 0 | E18: 1 | I18: 📊 يوضح الرسم البياني أعلاه: أ) الملفات المحالة حسب القطاع/الجهة — مقارنة الأرقام عبر الأعوام المتاحة في الجدول المقابل.
A19: المجموع | B19: 59 | C19: 32 | D19: 37 | E19: 40
A22: ب) توزيع الملفات المحالة حسب نوع التكييف الجرمي
A23: القطاع/الجهة | B23: 2022 | C23: 2023 | D23: 2024 | E23: 2025
A24: اساءة استعمال السلطة | B24: 21 | C24: 8 | D24: 16 | E24: 6
A25: التزوير/إعطاء مصدقات كاذبة/استعمال سند مزور | B25: 30 | C25: 17 | D25: 18 | E25: 21
A26: إساءة الائتمان | B26: 19 | C26: 12 | D26: 4 | E26: 4
A27: الاختلاس | B27: 6 | C27: 0 | D27: 6 | E27: 4
A28: التهاون في أداء الواجبات الوظيفية | B28: 9 | C28: 3 | D28: 10 | E28: 10
A29: غسل الأموال | B29: 1 | C29: 1 | D29: 1 | E29: 2
A30: الكسب غير المشروع | B30: 6 | C30: 8 | D30: 6 | E30: 9
A31: الاستثمار الوظيفي / الحصول على منفعة شخصية / الاتجار غير المشروع | B31: 2 | C31: 4 | D31: 2 | E31: 9
A32: الحصول على منفعة شخصية (منفصلاً) | B32: 1 | C32: 3 | D32: 3 | E32: 0
A33: إعاقة سير العدالة | B33: 1 | C33: 0 | D33: 0 | E33: 1
A34: الرشوة | B34: 2 | C34: 3 | D34: 1 | E34: 4
A35: قبول الواسطة والمحسوبية والمحاباة | B35: 1 | C35: 3 | D35: 2 | E35: 1 | I35: 📊 يوضح الرسم البياني أعلاه: ب) الملفات المحالة حسب نوع الجرم — مقارنة الأرقام عبر الأعوام المتاحة في الجدول المقابل.
A36: عدم الإفصاح عن تضارب المصالح | B36: 5 | C36: 5 | D36: 4 | E36: 3
A37: المتاجرة بالنفوذ | B37: 0 | C37: 0 | D37: 0 | E37: 1
A38: المجموع | B38: 104 | C38: 67 | D38: 73 | E38: 75
A40: ملاحظة: بعض الملفات تشمل أكثر من قطاع أو أكثر من تكييف جرمي واحد، لذا قد يفوق مجموع الجدول عدد الملفات الفعلي. كما تم تصحيح قيمة 'الاستثمار الوظيفي' ضمن تكييفات عام 2024 (كانت مُعلّمة خطأً '0' والصحيح 2).
A41: تنبيه بشأن جودة بيانات المصدر: جدول توزيع القطاعات لعام 2024 أعلاه ينص حرفيًا في التقرير الأصلي على مجموع (73)، إلا أن مجموع البنود المفردة المذكورة فيه (هيئات محلية 20 + مؤسسة عامة 1 + قطاع عام 13 + مكلف بخدمة عامة 1 + جمعيات خيرية 1 + حارس قضائي 1) يساوي (37) فقط. يبدو أن الرقم (73) في التقرير الأصلي مكرر من مجموع جدول تكييف الجرائم المجاور (الذي يصح مجموعه فعليًا 73). هذا تناقض وارد في التقرير الأصلي نفسه وليس ناتجًا عن معالجتنا؛ يُنصح بمراجعة النسخة الأصلية للتأكد من الرقم الصحيح لمجموع القطاعات.

Sheet 4-الملفات التحقيقية الواردة
A1: 4. عدد الملفات التحقيقية لدى الهيئة (الملفات الواردة) | G1: ⬆ رجوع للملخص العام
A2: عدد الملفات التحقيقية المسجّلة/الواردة للإدارة العامة للتحقيق سنويًا
A4: البيان | B4: 2022 | C4: 2023 | D4: 2024 | E4: 2025
A5: عدد الملفات الواردة | B5: 234 | C5: 197 | D5: 129 | E5: 153
A6: عدد الشكاوى والبلاغات (سجل أحوال) المرتبطة | B6: 325 | C6: 244 | D6: 151 | E6: 194
A7: منها: شكاوى وبلاغات جديدة | B7: 299 | C7: 239 | D7: غير متوفر | E7: غير متوفر
A8: منها: شكاوى وبلاغات ملحقة بملفات تحقيقية سابقة | B8: 26 | C8: 5 | D8: غير متوفر | E8: غير متوفر
A10: ملاحظة: تفصيل (جديد/ملحق بملف سابق) ورد صراحة في تقريري 2022 و2023 فقط ضمن نص الملفات الواردة؛ تقريرا 2024 و2025 اكتفيا بذكر الإجمالي دون هذا التفصيل.
I18: 📊 يوضح الرسم البياني أعلاه: 4. عدد الملفات التحقيقية لدى الهيئة (الملفات الواردة) — مقارنة الأرقام عبر الأعوام المتاحة في الجدول المقابل.

Sheet 5-الملفات المنجزة (عدد)
A1: 5. عدد الملفات التحقيقية المنجزة لدى الهيئة | G1: ⬆ رجوع للملخص العام
A2: عدد الملفات (بدلاً من النسبة المئوية بحسب طلبكم) - عدد ملفات التحقيق الأولي التي أُنجزت خلال فترة التقرير
A4: البيان | B4: 2022 | C4: 2023 | D4: 2024 | E4: 2025
A5: عدد ملفات التحقيق الأولي المنجزة | B5: 229 | C5: 174 | D5: 143 | E5: 173
A6: عدد القرارات الصادرة بشأنها | B6: 219 | C6: 171 | D6: 137 | E6: 168
A7: عدد الشكاوى والبلاغات المغلقة بموجبها | B7: 298 | C7: 217 | D7: 170 | E7: 222
I18: 📊 يوضح الرسم البياني أعلاه: 5. عدد الملفات التحقيقية المنجزة لدى الهيئة — مقارنة الأرقام عبر الأعوام المتاحة في الجدول المقابل.

Sheet 6-الواردة لنيابة جرائم الفساد
A1: 6. عدد القضايا التحقيقية الواردة لنيابة جرائم الفساد | G1: ⬆ رجوع للملخص العام
A2: عدد الملفات/القضايا المحالة من الإدارة العامة للتحقيق إلى النائب العام سنويًا
A4: البيان | B4: 2022 | C4: 2023 | D4: 2024 | E4: 2025
A5: عدد الملفات المحالة للنائب العام | B5: 61 | C5: 33 | D5: 38 | E5: 38
A6: عدد قرارات الإحالة الصادرة | B6: 58 | C6: 32 | D6: 32 | E6: 38
A7: عدد الأشخاص المشتبه بهم المحالين | B7: 93 | C7: 58 | D7: 68 | E7: 75
A8: منهم إناث (مصنّف حسب الجنس - متوفر لعام 2025 فقط) | B8: غير متوفر | C8: غير متوفر | D8: غير متوفر | E8: 12
A9: منهم ذكور (مصنّف حسب الجنس - متوفر لعام 2025 فقط) | B9: غير متوفر | C9: غير متوفر | D9: غير متوفر | E9: 63
A11: ملاحظة: التقارير المرفقة صادرة عن الإدارة العامة للتحقيق في هيئة مكافحة الفساد (وليست عن نيابة جرائم الفساد نفسها)، لذا فإن الرقم الممثَّل هو 'عدد الملفات المحالة من الهيئة إلى النائب العام' وقد يختلف عن رقم 'القضايا الواردة' لدى سجلات النيابة ذاتها.
I18: 📊 يوضح الرسم البياني أعلاه: 6. عدد القضايا التحقيقية الواردة لنيابة جرائم الفساد — مقارنة الأرقام عبر الأعوام المتاحة في الجدول المقابل.

Sheet 7-نسبة المنجز لدى النيابة
A1: 7. نسبة ملفات التحقيق الجزائي المنجزة لدى نيابة جرائم الفساد | G1: ⬆ رجوع للملخص العام
A2: نسبة القضايا المنجزة من إجمالي الواردة إلى نيابة جرائم الفساد
A4: البيان | B4: 2022 | C4: 2023 | D4: 2024 | E4: 2025
A5: النسبة المئوية | B5: =ROUND(B8/B6*100,1) -> 50.6 | C5: =ROUND(C8/C6*100,1) -> 123.1 | D5: =ROUND(D8/D6*100,1) -> 130.2 | E5: =ROUND(E8/E6*100,1) -> 122
A6: عدد القضايا الواردة (المستخدمة بالحساب) | B6: ='34-نموذج1 قضايا ومشتبهين'!B7 -> 87 | C6: ='34-نموذج1 قضايا ومشتبهين'!C7 -> 52 | D6: ='34-نموذج1 قضايا ومشتبهين'!D7 -> 43 | E6: ='34-نموذج1 قضايا ومشتبهين'!E7 -> 41
A7: ملاحظة وشرح طريقة الاحتساب: 1) عدد القضايا الواردة (الصف 6) = مرجع مباشر لخلية "القضايا الواردة - المجموع" في شيت "34-نموذج1 قضايا ومشتبهين" (صف 7). 2) عدد القضايا المنجزة (الصف 8) = مجموع (إحالة لمحكمة جرائم الفساد + حفظ + إحالة لجهات أخرى) من نفس الشيت 34 (الصفوف 10 إلى 12)، لأن هذه الإجراءات الثلاثة تمثل مجتمعة "إنجاز" الملف لدى النيابة. 3) النسبة المئوية (الصف 5) = (عدد القضايا المنجزة ÷ عدد القضايا الواردة) × 100، محسوبة تلقائيًا بمعادلة Excel حية ترتبط بشيت 34، بحيث لو تغيّر أي رقم مصدري هناك تتحدّث النسبة هنا تلقائيًا. تحفظ مهم: النسبة تجاوزت 100% في أعوام 2023 و2024 و2025، لأن عدد الملفات المنجزة في السنة قد يشمل ملفات متراكمة من سنوات سابقة (Backlog) وليس فقط الملفات الواردة في نفس السنة. لذا فهذه نسبة تقريبية لمستوى النشاط السنوي وليست نسبة "إنجاز فوري" دقيقة بالمعنى الرسمي الصارم للمؤشر.
A8: عدد القضايا المنجزة (المستخدمة بالحساب) | B8: =SUM('34-نموذج1 قضايا ومشتبهين'!B10:B12) -> 44 | C8: =SUM('34-نموذج1 قضايا ومشتبهين'!C10:C12) -> 64 | D8: =SUM('34-نموذج1 قضايا ومشتبهين'!D10:D12) -> 56 | E8: =SUM('34-نموذج1 قضايا ومشتبهين'!E10:E12) -> 50
I18: 📊 يوضح الرسم البياني أعلاه: 7. نسبة ملفات التحقيق الجزائي المنجزة لدى نيابة جرائم الفساد — مقارنة الأرقام عبر الأعوام المتاحة في الجدول المقابل.

Sheet 8-المحالين لمحكمة الفساد
A1: 8. عدد المتهمين المحالين من نيابة جرائم الفساد إلى محكمة جرائم الفساد | G1: ⬆ رجوع للملخص العام
A2: مجموع عدد المتهمين المحالين سنويًا إلى محكمة جرائم الفساد
A4: البيان | B4: 2022 | C4: 2023 | D4: 2024 | E4: 2025
A5: عدد المتهمين المحالين | B5: 60 | C5: 90 | D5: 74 | E5: 84
A6: عدد المتهمين المحالين - ذكور | B6: 59 | C6: 89 | D6: 68 | E6: 76
A8: عدد المتهمين المحالين - إناث | B8: 1 | C8: 1 | D8: 6 | E8: 8
A10: ملاحظة: تم تحديث هذا المؤشر بالاستناد إلى نموذج إحصائي رسمي إضافي صادر عن هيئة مكافحة الفساد (نموذج رقم 1: ملخص القضايا والمشتبه بهم والمتهمين)، يوضح عدد المتهمين المحالين فعليًا للمحكمة مصنّفين حسب الجنس.
A12: تنبيه تدقيق (مقارنة مع التقارير السنوية الأصلية): 2022 التقرير السنوي يذكر 62 متهماً (60+2 أشخاص معنويين لم يُدرجوا هنا) - ص44. 2023 التقرير السنوي يذكر 101 متهماً (89 ذكور + 12 إناث) بينما هنا 90 (89 ذكور + 1 أنثى فقط) - خطأ في عدد الإناث - ص50. 2024 التقرير السنوي يذكر 65 متهماً (59 ذكور + 6 إناث) بينما هنا 74 (68 ذكور + 6 إناث) - خطأ في عدد الذكور - ص64. يوصى بمطابقة نموذج رقم 1 مع نص التقرير السنوي قبل الاعتماد النهائي.
I18: 📊 يوضح الرسم البياني أعلاه: 8. عدد المتهمين المحالين من نيابة جرائم الفساد إلى محكمة جرائم الفساد — مقارنة الأرقام عبر الأعوام المتاحة في الجدول المقابل.

Sheet 9-القضايا المفصولة بحكم
A1: 9. عدد القضايا المفصولة بحكم في محكمة جرائم الفساد | G1: ⬆ رجوع للملخص العام
A2: مجموع عدد القضايا المفصولة بحكم نهائي
A4: البيان | B4: 2022 | C4: 2023 | D4: 2024 | E4: 2025
A5: عدد القضايا المفصولة | B5: 17 | C5: 10 | D5: 13 | E5: 26
A6: نتيجة الحكم: إدانة | B6: 7 | C6: 6 | D6: 8 | E6: 12
A8: نتيجة الحكم: براءة | B8: 9 | C8: 4 | D8: 2 | E8: 14
A9: عدم اختصاص | B9: 1 | C9: 0 | D9: 3 | E9: 0
A10: الطعن في الحكم (براءة) | B10: 1 | C10: 1 | D10: 1 | E10: 0
A11: الطعن في الحكم (إدانة) | B11: 0 | C11: 1 | D11: 0 | E11: 0
A12: تنبيه تدقيق: 2023 التقرير السنوي يذكر إجمالي 11 حكماً (6 إدانة + 4 براءة + 1 انقضاء دعوى) بينما هنا المجموع 10 (ينقص حكم "انقضاء الدعوى الجزائية" غير مدرج ضمن الأعمدة) - ص50. 2024 التقرير السنوي يذكر إجمالي 12 حكماً (8 إدانة + 2 براءة + 1 انقضاء دعوى + 1 عدم اختصاص) بينما هنا المجموع 13 - يوجد فرق حكم واحد - ص65. يوصى بإضافة عمود "انقضاء الدعوى الجزائية" ومطابقة الأرقام مع النص الأصلي.
I18: 📊 يوضح الرسم البياني أعلاه: 9. عدد القضايا المفصولة بحكم في محكمة جرائم الفساد — مقارنة الأرقام عبر الأعوام المتاحة في الجدول المقابل.

Sheet 10-المدانين
A1: 10. عدد المدانين في القضايا المفصولة بحكم في محكمة جرائم الفساد | G1: ⬆ رجوع للملخص العام
A2: مجموع عدد المدانين في القضايا المفصولة بحكم
A4: البيان | B4: 2022 | C4: 2023 | D4: 2024 | E4: 2025
A5: عدد المدانين | B5: 10 | C5: 11 | D5: 12 | E5: 13
A6: عدد المدانين - ذكور | B6: 10 | C6: 11 | D6: 12 | E6: 13
A8: عدد المدانين - إناث | B8: 0 | C8: 0 | D8: 0 | E8: 0
A10: ملاحظة: تم تحديث هذا المؤشر بالاستناد إلى نموذج إحصائي رسمي إضافي صادر عن هيئة مكافحة الفساد (نموذج رقم 2: نتائج الأحكام وعدد المدانين)، مصنّفًا حسب الجنس.
A12: تنبيه تدقيق: 2023 التقرير السنوي يذكر عدد المدانين 10 (وليس 11) - نص ص50/65: "10 متهمين ذكوراً حُكم عليهم بالإدانة". باقي الأعوام (2022=10، 2024=12) مطابقة للتقرير السنوي.
I18: 📊 يوضح الرسم البياني أعلاه: 10. عدد المدانين في القضايا المفصولة بحكم في محكمة جرائم الفساد — مقارنة الأرقام عبر الأعوام المتاحة في الجدول المقابل.

Sheet 11-المكلفين بالإقرار
A1: 11. عدد المكلفين بإقرارات الذمة المالية | G1: ⬆ رجوع للملخص العام
A2: عدد المكلفين بإقرارات الذمة المالية بموجب إشعار خلال الفترة
A4: البيان | B4: 2022 | C4: 2023 | D4: 2024 | E4: 2025
A5: عدد المكلفين | B5: 3933 | C5: 3327 | D5: 4504 | E5: غير 2177
A7: ملاحظة: عدد الأفراد المكلفين ما زال غير متوفر. المتوفر لدينا هو عدد "الجهات" المكلفة (وليس عدد الأشخاص) — أُضيف كمؤشر منفصل رقم 11ب.

Sheet 12-الإقرارات الموزعة
A1: 12. عدد إقرارات الذمة المالية الموزعة على المكلفين في الجهات الخاضعة | G1: ⬆ رجوع للملخص العام
A2: عدد الإقرارات التي قامت الهيئة بتوزيعها على المكلفين
A4: البيان | B4: 2022 | C4: 2023 | D4: 2024 | E4: 2025
A5: عدد نماذج إقرارات الذمة المالية الموزعة (المسلمة للمكلفين) | B5: 3933 | C5: 3327 | D5: 4504 | E5: 2177
A7: المصدر: بيانات مزودة من المستخدم استناداً إلى تقارير الهيئة (2022-2025).
I18: 📊 يوضح الرسم البياني أعلاه: 12. عدد إقرارات الذمة المالية الموزعة على المكلفين في الجهات الخاضعة — مقارنة الأرقام عبر الأعوام المتاحة في الجدول المقابل.

Sheet 13-نسبة الإقرارات المستوفاة
A1: 13. نسبة إقرارات الذمة المالية المستوفاة | G1: ⬆ رجوع للملخص العام
A2: عدد الإقرارات المستلمة فعليًا ÷ عدد الإقرارات المطلوبة × 100%
A4: البيان | B4: 2022 | C4: 2023 | D4: 2024 | E4: 2025
A5: إجمالي الإقرارات المستلمة فعلياً | B5: 3269 | C5: 2836 | D5: 2542 | E5: 2082
A6: النسبة المئوية (المستلمة ÷ الموزعة) | B6: =B5/'12-الإقرارات الموزعة'!B5 -> 0.83117213 | C6: =C5/'12-الإقرارات الموزعة'!C5 -> 0.8524196 | D6: =D5/'12-الإقرارات الموزعة'!D5 -> 0.56438721 | E6: =E5/'12-الإقرارات الموزعة'!E5 -> 0.95636197
A8: المصدر: بيانات مزودة من المستخدم استناداً إلى تقارير الهيئة (2022-2025).
I18: 📊 يوضح الرسم البياني أعلاه: 13. نسبة إقرارات الذمة المالية المستوفاة — مقارنة الأرقام عبر الأعوام المتاحة في الجدول المقابل.

Sheet 14-فض الإقرارات للفحص
A1: 14. نسبة إقرارات الذمة المالية التي تم فضها لأغراض الفحص الدوري | G1: ⬆ رجوع للملخص العام
A2: عدد الإقرارات التي تم فضها ÷ إجمالي الإقرارات المستلمة × 100 (النسبة غير قابلة للاحتساب لعدم توفر المقام/الإجمالي في التقارير)
A10: تنبيه: تم تزويدنا ببيانات فحص جديدة (أدناه) من مصدر آخر (تقرير فحص إقرارات الذمة المالية) تختلف عن الأرقام أعلاه (مثال: عدد الأشخاص عام 2023 = 21 حسب المصدر الجديد مقابل 18 أعلاه، وعام 2024 = 3 مقابل 10 أعلاه). كما أن المصدر الجديد يغطي عامي 2022 و2025 اللذين كانا غير متوفرين. يُنصح بالتحقق من التقرير الأصلي لتحديد المصدر الأدق قبل اعتماد رقم واحد نهائي.
A12: بيانات فحص إقرارات الذمة المالية (مصدر جديد)
A13: البيان | B13: 2022 | C13: 2023 | D13: 2024 | E13: 2025
A14: عدد الإقرارات المفحوصة | B14: 48 | C14: 36 | D14: 4 | E14: 92
A15: عدد الأشخاص (المكلفين) | B15: 30 | C15: 21 | D15: 3 | E15: 49
A16: الفحص بناءً على شكوى | B16: 28 | C16: 17 | D16: 2 | E16: 72
A17: الفحص بناءً على بلاغ/تحري | B17: 20 | C17: 19 | D17: 2 | E17: 14
A18: فحص بطلب من نيابة الفساد | B18: - | C18: - | D18: - | E18: 6 | I18: 📊 يوضح الرسم البياني أعلاه: فض/فحص الإقرارات (بيانات جزئية 2023-2024) — مقارنة الأرقام عبر الأعوام المتاحة في الجدول المقابل.
A19: عدد الذكور | B19: 24 | C19: 19 | D19: 3 | E19: 39
A20: عدد الإناث | B20: 6 | C20: 2 | D20: 0 | E20: 10
A22: المصدر: بيانات مزودة من المستخدم استناداً إلى تقارير الهيئة (2022-2025).
I35: 📊 يوضح الرسم البياني أعلاه: فحص الإقرارات حسب السبب والجنس (بيانات جديدة 2022-2025) — مقارنة الأرقام عبر الأعوام المتاحة في الجدول المقابل.

Sheet 15-طلبات الحماية الواردة
A1: 15. عدد طلبات الحماية الواردة للهيئة | G1: ⬆ رجوع للملخص العام
A2: مجموع عدد طلبات الحماية الواردة من المبلغين والمشتكين والأشخاص وثيقي الصلة بهم - مصدر البيانات: نموذج رقم (1) - وحدة حماية الشهود والمبلغين
A4: البيان | B4: 2022 | C4: 2023 | D4: 24 | E4: 2025
A5: عدد طلبات الحماية - ذكور | B5: 21 | C5: 12 | D5: 26 | E5: 22
A6: عدد طلبات الحماية - إناث | B6: 32 | C6: 15 | D6: 26 | E6: 28
A7: إجمالي عدد طلبات الحماية الواردة
A9: ملاحظة: بيانات هذا الجدول مأخوذة حرفيًا من 'نموذج رقم (1): طلبات الحماية الواردة حسب الجنس' الصادر عن وحدة حماية الشهود والمبلغين، وليست ضمن التقارير السنوية للإدارة العامة للتحقيق. تنبيه بشأن بيانات المصدر: في عام 2024 مجموع (ذكر 26 + أنثى 2 = 28) لا يطابق رقم الإجمالي المذكور صراحة في النموذج الأصلي (26)؛ تم إثبات الرقمين كما وردا حرفيًا في المصدر دون تعديل، وهذا التناقض وارد في المصدر نفسه.
A12: تم تعبئة صف "إجمالي عدد طلبات الحماية الواردة" (كان فارغاً): 2022=32، 2023=15، 2024=26، 2025=28 (مجموع ذكور+إناث في كل عام حسب التقارير السنوية). كما تم تصحيح عدد الذكور لعام 2024 من 26 إلى 24 وفق نص التقرير السنوي 2024 (ص45) الذي ينص صراحة على أن المجموع 26 يتوزع إلى 24 ذكور و2 إناث.
I18: 📊 يوضح الرسم البياني أعلاه: 15. عدد طلبات الحماية الواردة للهيئة — مقارنة الأرقام عبر الأعوام المتاحة في الجدول المقابل.

Sheet 15ب-حسب النوع والنتيجة
A1: 15ب. طلبات الحماية الواردة حسب نوع الحماية والنتيجة
A2: مصدر البيانات: نموذج رقم (2) - وحدة حماية الشهود والمبلغين
A4: السنة | B4: النتيجة | C4: حماية وظيفية | D4: حماية شخصية | E4: حماية قانونية | F4: المجموع
A5: 2022 | B5: قبول | C5: 2 | D5: 1 | E5: 0 | F5: 3
B6: رفض | C6: 24 | D6: 1 | E6: 4 | F6: 29
B7: مجموع | C7: 26 | D7: 2 | E7: 4 | F7: 32
A8: 2023 | B8: قبول | C8: 0 | D8: 0 | E8: 0 | F8: 0
B9: رفض | C9: 8 | D9: 8 | E9: 6 | F9: 22
B10: مجموع | C10: 8 | D10: 8 | E10: 6 | F10: 22
A11: 2024 | B11: قبول | C11: 2 | D11: 0 | E11: 0 | F11: 0
B12: رفض | C12: 13 | D12: 8 | E12: 3 | F12: 26
B13: مجموع | C13: 15 | D13: 8 | E13: 3 | F13: 26
A14: 2025 | B14: قبول | C14: 3 | D14: 0 | E14: 0 | F14: 3
B15: رفض | C15: 14 | D15: 9 | E15: 7 | F15: 30
B16: المجموع | C16: 17 | D16: 9 | E16: 7 | F16: 33
A18: ملاحظة: البيانات كما وردت حرفيًا في النموذج الأصلي. لعام 2024، صف 'قبول' يُظهر (وظيفية 2 + شخصية 0 + قانونية 0) لكن عمود المجموع المذكور صراحة في المصدر هو (0) - وهو تناقض وارد في المصدر نفسه دون تعديل من قبلنا. | I18: 📊 يوضح الرسم البياني أعلاه: 15ب. طلبات الحماية الواردة حسب نوع الحماية والنتيجة — مقارنة الأرقام عبر الأعوام المتاحة في الجدول المقابل.
A20: سنة | B20: حماية وظيفية (رفض) | C20: حماية شخصية (رفض) | D20: حماية قانونية (رفض)
A21: 2022 | B21: =C5 -> 2 | C21: =D5 -> 1 | D21: =E5 -> 0
A22: 2023 | B22: =C8 -> 0 | C22: =D8 -> 0 | D22: =E8 -> 0
A23: 2024 | B23: =C11 -> 2 | C23: =D11 -> 0 | D23: =E11 -> 0
A24: 2025 | B24: =C14 -> 3 | C24: =D14 -> 0 | D24: =E14 -> 0

Sheet 15ج-حسب جهة الحماية
A1: 15ج. طلبات الحماية الواردة حسب الجهة المطلوب الحماية منها
A2: مصدر البيانات: نموذج رقم (3) - وحدة حماية الشهود والمبلغين. متوفر لعام 2023 فقط ضمن النموذج المرفق
A4: الجهة | B4: 2022 | C4: 2023 | D4: 2024 | E4: 2025
A5: وزارات أو هيئات رسمية | B5: غير متوفر | C5: 5 | D5: غير متوفر | E5: غير متوفر
A6: أجهزة ومؤسسات أمنية | B6: غير متوفر | C6: 0 | D6: غير متوفر | E6: غير متوفر
A7: جمعيات | B7: غير متوفر | C7: 0 | D7: غير متوفر | E7: غير متوفر
A8: هيئات محلية | B8: غير متوفر | C8: 5 | D8: غير متوفر | E8: غير متوفر
A9: شركات | B9: غير متوفر | C9: 0 | D9: غير متوفر | E9: غير متوفر
A10: أفراد | B10: غير متوفر | C10: 3 | D10: غير متوفر | E10: غير متوفر
A11: نقابات | B11: غير متوفر | C11: 1 | D11: غير متوفر | E11: غير متوفر
A12: أخرى | B12: غير متوفر | C12: 0 | D12: غير متوفر | E12: غير متوفر
A13: المجموع | B13: غير متوفر | C13: 14 | D13: غير متوفر | E13: غير متوفر
A15: ملاحظة: النموذج الأصلي لا يتضمن بيانات إلا لعام 2023؛ باقي الأعوام (2022، 2024، 2025) غير مثبتة ضمن النموذج المرفق.
I18: 📊 يوضح الرسم البياني أعلاه: 15ج. طلبات الحماية الواردة حسب الجهة المطلوب الحماية منها — مقارنة الأرقام عبر الأعوام المتاحة في الجدول المقابل.

Sheet 16-طلبات التظلم
A1: 16. عدد طلبات التظلم على طلبات الحماية الواردة للهيئة | G1: ⬆ رجوع للملخص العام
A2: مصدر البيانات: نموذج رقم (4) - وحدة حماية الشهود والمبلغين
A4: البيان | B4: 2022 | C4: 2023 | D4: 2024 | E4: 2025
A5: عدد طلبات التظلم | B5: 4 | C5: 0 | D5: 2 | E5: 1
A6: منها: قبول | B6: 1 | C6: - | D6: 0 | E6: 0
A7: منها: رفض | B7: 3 | C7: 0 | D7: 2 | E7: 1
A9: ملاحظة: بيانات هذا الجدول مأخوذة حرفيًا من نموذج رقم (4) الصادر عن وحدة حماية الشهود والمبلغين. الإجمالي (4+0+2+1=7) يطابق مجموع عمود 'عدد طلبات التظلم' الوارد في نموذج رقم (1) لنفس الوحدة.
I18: 📊 يوضح الرسم البياني أعلاه: 16. عدد طلبات التظلم على طلبات الحماية الواردة للهيئة — مقارنة الأرقام عبر الأعوام المتاحة في الجدول المقابل.

Sheet 17-متابعة طلبات الحماية
A1: 17. عدد طلبات الحماية التي تمت المتابعة عليها | G1: ⬆ رجوع للملخص العام
A2: مجموع عدد طلبات الحماية التي تمت متابعتها
A4: البيان | B4: 2022 | C4: 2023 | D4: 2024 | E4: 2025
A5: عدد الطلبات المتابَعة | B5: 66 | C5: 24 | D5: 36 | E5: غير متوفر
A6: عدد طلبات إعادة التقييم | B6: غير متوفر | C6: 12 | D6: 14 | E6: غير متوفر
A7: ملاحظة: غير متوفر لا في تقارير الإدارة العامة للتحقيق ولا في نموذج وحدة حماية الشهود والمبلغين ('نموذج رقم 4: طلبات الحماية التي تم المتابعة عليها') المرفق، والذي ورد فارغًا دون أي بيانات مثبتة.
A13: تصحيح: هذا المؤشر كان مصنفاً بالكامل "غير متوفر" لكن البيانات موجودة فعلياً في التقارير السنوية 2022 و2023 و2024 تحت عنوان "الطلبات المتفرعة عن ملفات/طلبات الحماية" (وليس فقط في نموذج رقم 4 المرفق). عام 2025 لا يزال غير متوفر في المصدر المتاح. تمت إضافة صف "إعادة التقييم" كبيانات تكميلية.

Sheet 18-انتشار الرشوة (رأي عام)
A1: 18. نسبة الأفراد (18 سنة فأكثر) حسب وجهة نظرهم من انتشار الرشوة | G1: ⬆ رجوع للملخص العام
A2: عدد من أفادوا بوجهة نظرهم من انتشار الرشوة ÷ إجمالي الأفراد (18+) × 100 - مسح كل خمس سنوات (SDGs) | I2: 📊 لا يمكن إنشاء رسم بياني لهذا المؤشر لعدم توفر أي بيانات رقمية له في التقارير المرفقة.
A4: البيان | B4: 2022 | C4: 2023 | D4: 2024 | E4: 2025
A5: النسبة المئوية | B5: غير متوفر | C5: غير متوفر | D5: غير متوفر | E5: غير متوفر
A7: ملاحظة: غير متوفر في التقارير المرفقة؛ هذا مؤشر مسحي (استطلاعي) يُجرى دوريًا (كل خمس سنوات) بالتنسيق مع الجهاز المركزي للإحصاء الفلسطيني ولا يظهر في تقارير الإدارة العامة للتحقيق.

Sheet 19-انتشار الرشوة الفعلي
A1: 19. نسبة الأشخاص الذين دفعوا رشوة فعليًا (معدل الانتشار الفعلي) | G1: ⬆ رجوع للملخص العام
A2: عدد من دفعوا/طُلب منهم رشوة ÷ عدد من لديهم اتصال بمسؤول حكومي × 100 - مسح كل خمس سنوات (SDGs) | I2: 📊 لا يمكن إنشاء رسم بياني لهذا المؤشر لعدم توفر أي بيانات رقمية له في التقارير المرفقة.
A4: البيان | B4: 2022 | C4: 2023 | D4: 2024 | E4: 2025
A5: النسبة المئوية | B5: غير متوفر | C5: غير متوفر | D5: غير متوفر | E5: غير متوفر
A7: ملاحظة: غير متوفر في التقارير المرفقة؛ هذا مؤشر مسحي (استطلاعي) وليس من سجلات الإدارة العامة للتحقيق.

Sheet 20-الواردة حسب القطاع
A1: 20. توزيع الملفات التحقيقية الواردة حسب القطاع (الجهة) | G1: ⬆ رجوع للملخص العام
A2: توزيع الملفات الواردة للإدارة العامة للتحقيق سنويًا حسب نوع القطاع/الجهة
A4: البيان | B4: 2022 | C4: 2023 | D4: 2024 | E4: 2025
A5: قطاع عام/وزارات ومؤسسات وزارية | B5: 130 | C5: 89 | D5: 0 | E5: 0
A6: القطاع العام (مجمّع) | B6: 0 | C6: 0 | D6: 63 | E6: 93
A7: قطاع عام/مؤسسة غير وزارية | B7: 1 | C7: 0 | D7: 0 | E7: 0
A8: قطاع عام/مؤسسة تعليمية | B8: 1 | C8: 0 | D8: 3 | E8: 0
A9: مؤسسة عامة | B9: 3 | C9: 1 | D9: 2 | E9: 0
A10: هيئات محلية | B10: 84 | C10: 78 | D10: 63 | E10: 45
A11: الجمعيات | B11: 9 | C11: 13 | D11: 7 | E11: 13
A12: محكمين | B12: 1 | C12: 1 | D12: 0 | E12: 0
A13: شركة/شركات مساهمة عامة | B13: 4 | C13: 4 | D13: 1 | E13: 0
A14: اتحادات ونقابات | B14: 6 | C14: 4 | D14: 3 | E14: 6
A15: أندية | B15: 0 | C15: 3 | D15: 1 | E15: 0
A16: هيئات أهلية | B16: 0 | C16: 1 | D16: 0 | E16: 0
A17: شركة مساهمة خاصة | B17: 0 | C17: 1 | D17: 0 | E17: 0
A18: محامون | B18: 0 | C18: 2 | D18: 0 | E18: 0 | I18: 📊 يوضح الرسم البياني أعلاه: 20. توزيع الملفات التحقيقية الواردة حسب القطاع (الجهة) — مقارنة الأرقام عبر الأعوام المتاحة في الجدول المقابل.
A19: لجان | B19: 0 | C19: 2 | D19: 0 | E19: 0
A20: مكلفين بخدمة عامة | B20: 0 | C20: 3 | D20: 0 | E20: 0
A21: حراس قضائيون | B21: 0 | C21: 0 | D21: 2 | E21: 0
A22: سفارات | B22: 0 | C22: 0 | D22: 1 | E22: 0
A23: شركة عقارات | B23: 0 | C23: 0 | D23: 1 | E23: 0
A24: الغرفة التجارية | B24: 0 | C24: 0 | D24: 1 | E24: 0
A25: مؤسسات منظمة التحرير | B25: 0 | C25: 0 | D25: 0 | E25: 1
A26: الشركات الخاصة غير الخاضعة | B26: 0 | C26: 0 | D26: 0 | E26: 1
A27: المجموع | B27: 239 | C27: 202 | D27: 148 | E27: 159
A29: ملاحظة: بعض الملفات تضم أكثر من قطاع للشكوى/البلاغ الواردة في سجل الأحوال، وتصنيف 'القطاع العام' جاء مجمّعًا في تقريري 2024 و2025 دون تفصيل فرعي كما في 2022 و2023.

Sheet 21-جرائم الملفات الواردة
A1: 21. تصنيف جرائم الفساد في الملفات الواردة للإدارة | G1: ⬆ رجوع للملخص العام
A2: توزيع الملفات الواردة سنويًا حسب نوع التكييف الجرمي (تكييف أولي عند الورود)
A4: البيان | B4: 2022 | C4: 2023 | D4: 2024 | E4: 2025
A5: اساءة استعمال السلطة | B5: 134 | C5: 106 | D5: 62 | E5: 70
A6: الاختلاس | B6: 12 | C6: 9 | D6: 4 | E6: 8
A7: إساءة الائتمان | B7: 27 | C7: 40 | D7: 18 | E7: 13
A8: التزوير/إعطاء مصدقات كاذبة/استعمال سند مزور | B8: 53 | C8: 38 | D8: 35 | E8: 58
A9: التهاون في أداء واجبات الوظيفة العمومية | B9: 23 | C9: 10 | D9: 17 | E9: 12
A10: عدم الإفصاح عن تضارب المصالح | B10: 15 | C10: 13 | D10: 25 | E10: 17
A11: الاستثمار الوظيفي | B11: 7 | C11: 8 | D11: 4 | E11: 0
A12: قبول الواسطة والمحسوبية (والمحاباة) | B12: 25 | C12: 26 | D12: 11 | E12: 9
A13: الكسب غير المشروع | B13: 14 | C13: 12 | D13: 5 | E13: 22
A14: الحصول على منفعة شخصية (منفصلاً) | B14: 2 | C14: 0 | D14: 3 | E14: 0
A15: الاستثمار الوظيفي / الحصول على منفعة شخصية / الاتجار غير المشروع (مدمج) | B15: 0 | C15: 0 | D15: 0 | E15: 16
A16: الرشوة | B16: 10 | C16: 15 | D16: 8 | E16: 13
A17: المتاجرة بالنفوذ | B17: 3 | C17: 2 | D17: 1 | E17: 2
A18: عدم الاختصاص | B18: 6 | C18: 0 | D18: 0 | E18: 0 | I18: 📊 يوضح الرسم البياني أعلاه: 21. تصنيف جرائم الفساد في الملفات الواردة للإدارة — مقارنة الأرقام عبر الأعوام المتاحة في الجدول المقابل.
A19: إعاقة سير العدالة | B19: 0 | C19: 1 | D19: 0 | E19: 1
A20: غسل الأموال | B20: 0 | C20: 0 | D20: 0 | E20: 4
A21: المجموع | B21: 331 | C21: 280 | D21: 193 | E21: 245
A23: ملاحظة: تم تصحيح هذا الجدول - كانت بيانات عام 2024 مثبتة سابقًا خطأً في عمود 2023، وكان عمود 2024 مُعلّمًا كـ'0' رغم أن تقرير 2024 يتضمن هذا الجدول فعليًا (المجموع 193). بيانات عام 2023 الحقيقية (المجموع 280) أُضيفت الآن. لعام 2025 وردت فئتا 'الاستثمار الوظيفي' و'الحصول على منفعة شخصية' والاتجار غير المشروع مدمجة في تكييف واحد (16)، بخلاف بقية السنوات حيث وردت منفصلة. بعض الملفات تشمل أكثر من تكييف جرمي واحد.

Sheet 22-المحفوظة حسب قطاع وجرم
A1: 22. توزيع الملفات المحفوظة (قرار حفظ) حسب القطاع وحسب نوع الجرم | G1: ⬆ رجوع للملخص العام
A2: متوفر بالتفصيل الكامل لعام 2022 فقط؛ باقي السنوات لم يرد فيها هذا المستوى من التفصيل ضمن التقارير المرفقة
A4: أ) حسب القطاع (الجهة)
A5: البيان | B5: 2022 | C5: 2023 | D5: 2024 | E5: 2025
A6: قطاع عام/وزارات ومؤسسات وزارية | B6: 80 | C6: غير متوفر | D6: غير متوفر | E6: غير متوفر
A7: هيئات محلية | B7: 51 | C7: غير متوفر | D7: غير متوفر | E7: غير متوفر
A8: جمعيات | B8: 8 | C8: غير متوفر | D8: غير متوفر | E8: غير متوفر
A9: اتحادات ونقابات | B9: 1 | C9: غير متوفر | D9: غير متوفر | E9: غير متوفر
A10: لجان | B10: 2 | C10: غير متوفر | D10: غير متوفر | E10: غير متوفر
A11: مؤسسة عامة | B11: 1 | C11: غير متوفر | D11: غير متوفر | E11: غير متوفر
A12: قطاع عام/مؤسسة تعليمية | B12: 1 | C12: غير متوفر | D12: غير متوفر | E12: غير متوفر
A13: المجموع | B13: 144 | C13: غير متوفر | D13: غير متوفر | E13: غير متوفر
A15: ب) حسب نوع التكييف الجرمي
A16: البيان | B16: 2022 | C16: 2023 | D16: 2024 | E16: 2025
A17: اساءة استعمال السلطة | B17: 100 | C17: غير متوفر | D17: غير متوفر | E17: غير متوفر
A18: إساءة الائتمان | B18: 9 | C18: غير متوفر | D18: غير متوفر | E18: غير متوفر | I18: 📊 يوضح الرسم البياني أعلاه: أ) الملفات المحفوظة حسب القطاع — مقارنة الأرقام عبر الأعوام المتاحة في الجدول المقابل.
A19: الاختلاس | B19: 3 | C19: غير متوفر | D19: غير متوفر | E19: غير متوفر
A20: الكسب غير المشروع | B20: 14 | C20: غير متوفر | D20: غير متوفر | E20: غير متوفر
A21: التهاون في أداء الواجبات الوظيفية | B21: 22 | C21: غير متوفر | D21: غير متوفر | E21: غير متوفر
A22: عدم الإفصاح عن تضارب المصالح | B22: 5 | C22: غير متوفر | D22: غير متوفر | E22: غير متوفر
A23: قبول الواسطة والمحسوبية | B23: 26 | C23: غير متوفر | D23: غير متوفر | E23: غير متوفر
A24: التزوير/إعطاء مصدقات كاذبة | B24: 19 | C24: غير متوفر | D24: غير متوفر | E24: غير متوفر
A25: الرشوة | B25: 4 | C25: غير متوفر | D25: غير متوفر | E25: غير متوفر
A26: الاستثمار الوظيفي | B26: 2 | C26: غير متوفر | D26: غير متوفر | E26: غير متوفر
A27: المتاجرة بالنفوذ | B27: 1 | C27: غير متوفر | D27: غير متوفر | E27: غير متوفر
A28: المجموع | B28: 205 | C28: غير متوفر | D28: غير متوفر | E28: غير متوفر
A30: ملاحظة: تقارير 2023 و2024 و2025 لم تتضمن تفصيل الملفات المحفوظة حسب القطاع/الجرم، واقتصرت على الرقم الإجمالي لعدد قرارات وملفات الحفظ ضمن الجدول العام.
I35: 📊 يوضح الرسم البياني أعلاه: ب) الملفات المحفوظة حسب نوع الجرم — مقارنة الأرقام عبر الأعوام المتاحة في الجدول المقابل.

Sheet 23-محولة للنيابة العامة
A1: 23. عدد الملفات المحوّلة إلى النيابة العامة لعدم تشكيل الفعل جريمة فساد | G1: ⬆ رجوع للملخص العام
A2: من ضمن الملفات المردودة لعدم الاختصاص، عدد الملفات التي حُوّلت إلى النيابة العامة كون الفعل يشكل جريمة أخرى غير جريمة فساد
A4: البيان | B4: 2022 | C4: 2023 | D4: 2024 | E4: 2025
A5: عدد الملفات المحوّلة للنيابة العامة | B5: 7 | C5: 3 | D5: 2 | E5: 8
A6: إجمالي الملفات المردودة لعدم الاختصاص (للمقارنة) | B6: 13 | C6: 5 | D6: 2 | E6: 8
I18: 📊 يوضح الرسم البياني أعلاه: 23. عدد الملفات المحوّلة إلى النيابة العامة لعدم تشكيل الفعل جريمة فساد — مقارنة الأرقام عبر الأعوام المتاحة في الجدول المقابل.

Sheet 24-إجراءات الضبط القضائي
A1: 24. أعمال الضبط القضائي والتحري والاستدلال (التحقيق الأولي) | G1: ⬆ رجوع للملخص العام
A2: إجراءات ميدانية وقضائية اتخذتها الإدارة العامة للتحقيق أثناء متابعة الملفات - متوفرة فقط في تقريري 2023 و2024
A4: البيان | B4: 2022 | C4: 2023 | D4: 2024 | E4: 2025
A5: عدد المراسلات القضائية الموجّهة لجهات مختلفة | B5: غير متوفر | C5: 342 | D5: 300 | E5: غير متوفر
A6: عدد الإفادات/الشهادات المسموعة في ملفات التحقيق الأولي | B6: غير متوفر | C6: 487 | D6: 530 | E6: غير متوفر
A7: عدد الأشخاص المُمنوعين من السفر | B7: غير متوفر | C7: 3 | D7: 0 | E7: غير متوفر
A8: قيمة الأموال المضبوطة في ملفات تحقيقية (شيقل) | B8: غير متوفر | C8: 55,000 (في 3 ملفات) | D8: 0 | E8: غير متوفر
A9: عدد قرارات فض وفحص إقرارات الذمة المالية (رئيس الهيئة) | B9: غير متوفر | C9: 17 | D9: 1 | E9: غير متوفر
A10: عدد الأشخاص المشمولين بفض/فحص إقراراتهم المالية | B10: غير متوفر | C10: 18 | D10: 10 | E10: غير متوفر
A11: عدد قرارات رفع السرية المصرفية الصادرة عن النيابة العامة | B11: غير متوفر | C11: 1 | D11: 0 | E11: غير متوفر
A12: استصدار قرار من النيابة العامة بالنفاذ المباشر لهاتف مشتبه به | B12: غير متوفر | C12: 0 | D12: 1 | E12: غير متوفر
A13: تكليف شخص مشتبه به بتقديم إقرار ذمة مالية جديد | B13: غير متوفر | C13: 0 | D13: نعم | E13: غير متوفر
A14: عدد طلبات وقف عمل موظفين لوجود شبهة فساد | B14: غير متوفر | C14: 0 | D14: 2 | E14: غير متوفر
A15: الاستعانة بالمختبر الجنائي لتقرير خبرة فنية (مضاهاة خطوط) | B15: غير متوفر | C15: نعم | D15: نعم | E15: غير متوفر
A16: تنفيذ جولة ميدانية بالاستعانة بموظفي مساحة الأراضي | B16: غير متوفر | C16: نعم | D16: 0 | E16: غير متوفر
A17: عدد الجهات المخاطَبة ضمن برنامج الوقاية من مخاطر الفساد | B17: غير متوفر | C17: 0 | D17: 14 | E17: غير متوفر
I18: 📊 يوضح الرسم البياني أعلاه: 24. أعمال الضبط القضائي والتحري والاستدلال (التحقيق الأولي) — مقارنة الأرقام عبر الأعوام المتاحة في الجدول المقابل.
A19: ملاحظة: هذا القسم (أعمال الضبط القضائي والتحري) لم يظهر إطلاقًا في تقريري 2022 و2025 المرفقين، وورد فقط ضمن تقريري 2023 و2024. تم تصحيح 'رفع السرية المصرفية' لتكون ضمن عام 2023 (وليس 2024 كما كان مثبتًا خطأً سابقًا)، وأُضيف إجراءان وردا في تقرير 2024 ولم يكونا مدرجين سابقًا: 'النفاذ المباشر لهاتف مشتبه به' و'تكليف شخص مشتبه به بتقديم إقرار ذمة مالية جديد'.

Sheet 25-نسب ومعدلات مشتقة
A1: 25. نسب ومعدلات مشتقة من بيانات التقارير السنوية | G1: ⬆ رجوع للملخص العام
A2: جميع النسب أدناه محسوبة بصيغ Excel ديناميكية اعتمادًا على الأرقام الأساسية المُدخلة (وليست أرقامًا ثابتة)
A4: البيانات الأساسية (مُدخلة من التقارير)
A5: البيان | B5: 2022 | C5: 2023 | D5: 2024 | E5: 2025
A6: الملفات التحقيقية الواردة | B6: 234 | C6: 197 | D6: 129 | E6: 153
A7: الشكاوى والبلاغات (سجل أحوال) المرتبطة | B7: 325 | C7: 244 | D7: 151 | E7: 194
A8: عدد قرارات الإحالة للنائب العام | B8: 58 | C8: 32 | D8: 32 | E8: 38
A9: عدد قرارات الحفظ | B9: 141 | C9: 133 | D9: 103 | E9: 120
A10: عدد قرارات الرد لعدم الاختصاص | B10: 13 | C10: 5 | D10: 2 | E10: 8
A11: عدد ملفات التحقيق الأولي المنجزة | B11: 229 | C11: 174 | D11: 143 | E11: 173
A13: النسب والمعدلات المحسوبة (Formulas)
A14: المؤشر | B14: 2022 | C14: 2023 | D14: 2024 | E14: 2025
A15: نسبة الإحالة للنائب العام من إجمالي الملفات الواردة | B15: =B8/B6 -> 0.24786325 | C15: =C8/C6 -> 0.16243655 | D15: =D8/D6 -> 0.24806202 | E15: =E8/E6 -> 0.24836601
A16: نسبة الحفظ من إجمالي الملفات الواردة | B16: =B9/B6 -> 0.6025641 | C16: =C9/C6 -> 0.6751269 | D16: =D9/D6 -> 0.79844961 | E16: =E9/E6 -> 0.78431373
A17: نسبة الرد لعدم الاختصاص من إجمالي الملفات الواردة | B17: =B10/B6 -> 0.055555556 | C17: =C10/C6 -> 0.025380711 | D17: =D10/D6 -> 0.015503876 | E17: =E10/E6 -> 0.052287582
A18: متوسط عدد الشكاوى/البلاغات لكل ملف تحقيقي واحد | B18: =B7/B6 -> 1.3888889 | C18: =C7/C6 -> 1.2385787 | D18: =D7/D6 -> 1.1705426 | E18: =E7/E6 -> 1.2679739 | I18: 📊 يوضح الرسم البياني أعلاه: أ) نسب ومعدلات مشتقة (المجموعة الأولى) — مقارنة الأرقام عبر الأعوام المتاحة في الجدول المقابل.
A19: نسبة الملفات المنجزة من إجمالي الملفات الواردة | B19: =B11/B6 -> 0.97863248 | C19: =C11/C6 -> 0.88324873 | D19: =D11/D6 -> 1.1085271 | E19: =E11/E6 -> 1.130719
A20: معدل النمو السنوي لعدد الملفات الواردة (عن السنة السابقة) | B20: غير متوفر | C20: =(C6-B6)/B6 -> -0.15811966 | D20: =(D6-C6)/C6 -> -0.34517766 | E20: =(E6-D6)/D6 -> 0.18604651
A21: الفرق بين عدد الملفات الواردة وعدد الملفات المنجزة (تراكم الملفات) | B21: =B6-B11 -> 5 | C21: =C6-C11 -> 23 | D21: =D6-D11 -> -14 | E21: =E6-E11 -> -20
A23: ملاحظة: الأرقام الزرقاء في قسم 'البيانات الأساسية' هي مُدخلات مأخوذة حرفيًا من التقارير السنوية الأربعة، أما النسب في القسم الثاني فهي صيغ Excel تُحسب تلقائيًا من هذه المُدخلات وستتحدث تلقائيًا في حال تعديل أي رقم أساسي.
I35: 📊 يوضح الرسم البياني أعلاه: ب) نسب ومعدلات مشتقة (المجموعة الثانية) — مقارنة الأرقام عبر الأعوام المتاحة في الجدول المقابل.

Sheet 26-منتهية (ملف مماثل بالنيابة)
A1: 26. عدد ملفات التحقيق الأولي المنتهية لوجود ملف تحقيقي آخر لدى نيابة جرائم الفساد بذات الموضوع | G1: ⬆ رجوع للملخص العام
A2: بند 'منتهية' الظاهر ضمن جدول القرارات الصادرة في كل التقارير الأربعة (لم يكن مدرجًا سابقًا كمؤشر مستقل في الملف رغم توفره في كل التقارير)
A4: البيان | B4: 2022 | C4: 2023 | D4: 2024 | E4: 2025
A5: عدد الملفات المنتهية | B5: 6 | C5: 1 | D5: غير متوفر | E5: 2
A6: عدد الشكاوى والبلاغات المغلقة بموجبها | B6: 6 | C6: 1 | D6: غير متوفر | E6: 2
A8: ملاحظة: يُقصد بهذا البند إنهاء أعمال التحقيق الأولي في الملف وإرسال كافة أعمال التحري والاستدلال إلى النائب العام، وذلك لوجود ملف تحقيقي آخر لدى نيابة جرائم الفساد يتعلق بذات الموضوع (وليس إحالة أو حفظ أو ردًا لعدم الاختصاص). المسمى في تقريري 2022/2023 'منتهية' وفي تقريري 2024/2025 'تحويل للنيابة العامة لوجود ملف تحقيقي لديهم بذات الموضوع'. [تم تصحيح: تقرير 2024 لا يتضمن فقرة 'انهاء أعمال التحقيق الأولي' منفصلة أصلاً (القيمة 2 المذكورة سابقًا كانت مأخوذة خطأً من شكاوى فئة الرد لعدم الاختصاص)؛ وتقرير 2025 ينص صراحة على إغلاق (2) شكوى وبلاغ بموجب هذا البند.]
I18: 📊 يوضح الرسم البياني أعلاه: 26. عدد ملفات التحقيق الأولي المنتهية لوجود ملف تحقيقي آخر لدى نيابة جرائم الفسا — مقارنة الأرقام عبر الأعوام المتاحة في الجدول المقابل.

Sheet 27-تفصيل حسب نوع القرار
A1: 27. تفصيل عدد الملفات وعدد الشكاوى/البلاغات المغلقة حسب نوع القرار (لكل سنة) | G1: ⬆ رجوع للملخص العام
A3: مستخرج حرفيًا من نص الفقرة الوصفية 'الملفات المنجزة' في كل تقرير سنوي (وليس من الجدول الرأسي المختصر)
A4: أ) عدد الملفات (ملفات تحقيق أولي) حسب نوع القرار
A5: نوع القرار | B5: 2022 | C5: 2023 | D5: 2024 | E5: 2025
A6: إحالة للنائب العام | B6: 61 | C6: 33 | D6: 38 | E6: 38
A7: حفظ | B7: 148 | C7: 135 | D7: 103 | E7: 125
A8: رد لعدم الاختصاص | B8: 13 | C8: 5 | D8: 2 | E8: 8
A9: منتهية / تحويل للنيابة لوجود ملف مماثل | B9: 6 | C9: 1 | D9: غير متوفر | E9: 2
A10: المجموع (حسب جمع البنود) | B10: 228 | C10: 174 | D10: 143 | E10: 173
A11: المجموع المذكور صراحة في التقرير | B11: 229 | C11: 174 | D11: 143 | E11: 173
A13: ب) عدد الشكاوى والبلاغات (سجل أحوال) المغلقة حسب نوع القرار
A14: نوع القرار | B14: 2022 | C14: 2023 | D14: 2024 | E14: 2025
A15: إحالة للنائب العام | B15: 96 | C15: 40 | D15: 52 | E15: 39
A16: حفظ | B16: 181 | C16: 171 | D16: 116 | E16: 173
A17: رد لعدم الاختصاص | B17: 14 | C17: 5 | D17: 2 | E17: 8
A18: منتهية / تحويل للنيابة لوجود ملف مماثل | B18: 6 | C18: 1 | D18: 2 | E18: 2 | I18: 📊 يوضح الرسم البياني أعلاه: أ) تفصيل حسب نوع القرار (شكاوى جديدة/ملحقة) — مقارنة الأرقام عبر الأعوام المتاحة في الجدول المقابل.
A19: المجموع (حسب جمع البنود) | B19: 297 | C19: 217 | D19: 170 | E19: 222
A20: المجموع المذكور صراحة في التقرير | B20: 298 | C20: 217 | D20: 170 | E20: 222
A22: ملاحظة: في عام 2022 هناك فارق بسيط بين مجموع البنود المفردة والمجموع المذكور صراحة في التقرير (228 مقابل 229 ملف، و297 مقابل 298 شكوى) — وهذا تناقض بسيط وارد في التقرير الأصلي نفسه (على الأرجح بسبب ملف واحد متداخل بين فئتين)، وليس ناتجًا عن معالجتنا. في باقي الأعوام (2023، 2024، 2025) مجموع البنود يطابق المجموع المذكور صراحة تمامًا.
A23: ملاحظة: تقرير 2024 لا يتضمن فقرة 'منتهية' مستقلة إطلاقًا ضمن نص الملفات المنجزة (القرارات الثلاثة إحالة+حفظ+رد فقط = 137، مطابق للمجموع المذكور)؛ فقيمة 'عدد الملفات' لهذا البند تُركت 'غير متوفر' تحرزًا، فيما ورد رقم الشكاوى (2) ضمن فئة الرد لعدم الاختصاص أصلاً وليس كبند مستقل - تم استخدامه هنا للتوضيح مع الإشارة أنه ليس بندًا منفصلاً كما في باقي السنوات.
A26: ]
I35: 📊 يوضح الرسم البياني أعلاه: ب) تفصيل حسب نوع القرار (نتائج الفحص) — مقارنة الأرقام عبر الأعوام المتاحة في الجدول المقابل.

Sheet 28-الشكاوى حسب مصدر التقديم
A1: 28. عدد الشكاوى والبلاغات الواردة لهيئة مكافحة الفساد حسب مصدر التقديم | G1: ⬆ رجوع للملخص العام
A2: مصدر البيانات: نموذج رقم (1) - الإدارة العامة للشكاوى والبلاغات والتحري. ملاحظة: هذا مؤشر على مستوى الشكاوى/البلاغات عند ورودها للهيئة ككل (قبل تسجيلها كملف تحقيقي)، وهو أوسع نطاقًا ومختلف عن مؤشر رقم (4) 'الملفات التحقيقية الواردة' الذي يقيس الملفات بعد فرزها؛ لا يجوز الجمع أو المقارنة المباشرة بين الرقمين.
A4: السنة | B4: أفراد - ذكر | C4: أفراد - أنثى | D4: أفراد - ذكر وأنثى معاً | E4: مؤسسات | F4: مجهول / غير معروف | G4: المجموع
A5: 2022 | B5: 346 | C5: 45 | D5: 8 | E5: 66 | F5: 414 | G5: 879
A6: 2023 | B6: 237 | C6: 19 | D6: 7 | E6: 43 | F6: 281 | G6: 587
A7: 2024 | B7: 278 | C7: 29 | D7: 10 | E7: 44 | F7: 309 | G7: 670
A8: 2025 | B8: 328 | C8: 47 | D8: 1 | E8: 37 | F8: 374 | G8: 787
A10: ملاحظة: عمود 'ذكر وأنثى معاً' يمثل شكاوى/بلاغات مقدّمة من أكثر من فرد (ذكر وأنثى) معًا، كما ورد حرفيًا في النموذج الأصلي.
I18: 📊 يوضح الرسم البياني أعلاه: 28. عدد الشكاوى والبلاغات الواردة لهيئة مكافحة الفساد حسب مصدر التقديم — مقارنة الأرقام عبر الأعوام المتاحة في الجدول المقابل.

Sheet 29-الشكاوى حسب التكييف الأولي
A1: 29. تصنيف الشكاوى والبلاغات الواردة حسب التكييف الأولي لجرم الفساد المشتبه به | G1: ⬆ رجوع للملخص العام
A2: مصدر البيانات: نموذج رقم (2) - الإدارة العامة للشكاوى والبلاغات والتحري. مؤشر على مستوى الشكاوى/البلاغات (قبل التحري)، مختلف عن مؤشر رقم (21) 'تصنيف جرائم الفساد في الملفات الواردة' الذي يقيّم الملفات بعد الفرز والتحري الأولي.
A4: التكييف القانوني | B4: 2022 | C4: 2023 | D4: 2024 | E4: 2025
A5: التهاون في القيام بالواجبات الوظيفية | B5: 15 | C5: 7 | D5: 10 | E5: 27
A6: الرشوة | B6: 16 | C6: 8 | D6: 12 | E6: 15
A7: الاختلاس | B7: 26 | C7: 6 | D7: 4 | E7: 17
A8: إساءة استعمال السلطة | B8: 668 | C8: 459 | D8: 577 | E8: 552
A9: التزوير والتزييف | B9: 41 | C9: 39 | D9: 25 | E9: 69
A10: قبول الواسطة والمحسوبية والمحاباة | B10: 39 | C10: 10 | D10: 11 | E10: 81
A11: استثمار الوظيفة | B11: 8 | C11: 0 | D11: 0 | E11: 0
A12: إساءة الائتمان | B12: 5 | C12: 1 | D12: 4 | E12: 7
A13: الكسب غير المشروع | B13: 5 | C13: 2 | D13: 1 | E13: 10
A14: عدم الإفصاح عن تضارب المصالح | B14: 16 | C14: 4 | D14: 3 | E14: 9
A15: غسل الأموال الناتجة عن جرائم فساد | B15: 0 | C15: 0 | D15: 0 | E15: 0
A16: المتاجرة بالنفوذ | B16: 0 | C16: 0 | D16: 0 | E16: 0
A17: إعاقة سير العدالة | B17: 0 | C17: 0 | D17: 0 | E17: 0
A18: عدم اختصاص قبل مرحلة التحري | B18: 40 | C18: 51 | D18: 23 | E18: 0 | I18: 📊 يوضح الرسم البياني أعلاه: 29. تصنيف الشكاوى والبلاغات الواردة حسب التكييف الأولي لجرم الفساد المشتبه به — مقارنة الأرقام عبر الأعوام المتاحة في الجدول المقابل.
A19: المجموع | B19: 0 | C19: 0 | D19: 0 | E19: 0
A21: ملاحظة: صف 'المجموع' ورد فارغًا (غير مثبت) في النموذج الأصلي المرفق، ولم نقم باحتسابه لتجنّب أي جمع غير موثّق قد يخالف الرقم الرسمي إن وُجد.

Sheet 30-الشكاوى حسب القطاع
A1: 30. توزيع الشكاوى والبلاغات الواردة حسب القطاع | G1: ⬆ رجوع للملخص العام
A2: مصدر البيانات: نموذج رقم (4) - الإدارة العامة للشكاوى والبلاغات والتحري. مؤشر على مستوى الشكاوى (قبل الفرز)، مختلف عن مؤشر رقم (20) 'توزيع الملفات الواردة حسب القطاع'.
A4: القطاع | B4: 2022 | C4: 2023 | D4: 2024 | E4: 2025
A5: مؤسسات عامة | B5: 455 | C5: 462 | D5: 353 | E5: 364
A6: هيئات محلية | B6: 299 | C6: 257 | D6: 237 | E6: 311
A7: مؤسسات المجتمع المدني | B7: 0 | C7: 30 | D7: 43 | E7: 53
A8: قطاع خاص | B8: 0 | C8: 13 | D8: 11 | E8: 20
A9: مؤسسات تعليمية ومراكز بحثية | B9: 13 | C9: 13 | D9: 17 | E9: 19
A10: مؤسسات دولية | B10: 0 | C10: 1 | D10: 2 | E10: 3
A11: مكلفون بأداء خدمة عامة | B11: 0 | C11: 1 | D11: 1 | E11: 1
A12: مؤسسات منظمة التحرير | B12: 0 | C12: 8 | D12: 6 | E12: 5
A13: غير خاضعين | B13: 12 | C13: 0 | D13: 0 | E13: 11
A14: أخرى | B14: 100 | C14: 0 | D14: 0 | E14: 0
A15: المجموع | B15: 0 | C15: 0 | D15: 0 | E15: 0
A17: ملاحظة: صف 'المجموع' ورد فارغًا في النموذج الأصلي المرفق ولم يُحتسب تفاديًا لأي جمع غير موثّق.
I18: 📊 يوضح الرسم البياني أعلاه: 30. توزيع الشكاوى والبلاغات الواردة حسب القطاع — مقارنة الأرقام عبر الأعوام المتاحة في الجدول المقابل.

Sheet 31-طريقة استلام الشكوى
A1: 31. توزيع الشكاوى والبلاغات الواردة حسب طريقة الاستلام | G1: ⬆ رجوع للملخص العام
A2: مصدر البيانات: نموذج رقم (5) - الإدارة العامة للشكاوى والبلاغات والتحري
A4: طريقة استلام الشكوى أو البلاغ | B4: 2022 | C4: 2023 | D4: 2024 | E4: 2025
A5: الحضور الشخصي وتسليم باليد | B5: 315 | C5: 210 | D5: 293 | E5: 268
A6: جهات ومؤسسات رسمية | B6: 65 | C6: 33 | D6: 53 | E6: 36
A7: الرصد | B7: 14 | C7: 0 | D7: 0 | E7: 2
A8: الوسائل والتطبيقات الإلكترونية | B8: 485 | C8: 344 | D8: 324 | E8: 481
A9: المجموع | B9: 0 | C9: 0 | D9: 0 | E9: 0
A11: ملاحظة: صف 'المجموع' ورد فارغًا في النموذج الأصلي؛ مجموع البنود المفردة لعام 2022 (315+65+14+485=879) يطابق إجمالي عدد الشكاوى الواردة لعام 2022 في نموذج رقم (1) لنفس المصدر.
I18: 📊 يوضح الرسم البياني أعلاه: 31. توزيع الشكاوى والبلاغات الواردة حسب طريقة الاستلام — مقارنة الأرقام عبر الأعوام المتاحة في الجدول المقابل.

Sheet 32-الشكاوى حسب جنس المشتكى عليه
A1: 32. توزيع الشكاوى والبلاغات الواردة حسب جنس المشتكى عليه | G1: ⬆ رجوع للملخص العام
A2: مصدر البيانات: نموذج رقم (6) - الإدارة العامة للشكاوى والبلاغات والتحري
A4: السنة | B4: أفراد - ذكر | C4: أفراد - أنثى | D4: أفراد - ذكر وأنثى معاً | E4: مؤسسات | F4: المجموع
A5: 2022 | B5: 387 | C5: 26 | D5: 20 | E5: 0 | F5: 446
A6: 2023 | B6: 260 | C6: 18 | D6: 10 | E6: 0 | F6: 299
A7: 2024 | B7: 314 | C7: 20 | D7: 15 | E7: 0 | F7: 321
A8: 2025 | B8: 365 | C8: 30 | D8: 21 | E8: 0 | F8: 371
A10: ملاحظة: خانة 'مؤسسات' لم تحمل قيمًا رقمية مستقلة في النموذج الأصلي لهذا الجدول تحديدًا (بخلاف جدول رقم 1)؛ أُبقيت '0' تحرزًا.
I18: 📊 يوضح الرسم البياني أعلاه: 32. توزيع الشكاوى والبلاغات الواردة حسب جنس المشتكى عليه — مقارنة الأرقام عبر الأعوام المتاحة في الجدول المقابل.

Sheet 33-حسب درجة المشتكى عليه
A1: 33. توزيع الشكاوى والبلاغات الواردة حسب الدرجة الوظيفية للمشتكى عليه | G1: ⬆ رجوع للملخص العام
A2: مصدر البيانات: نموذج رقم (7) - الإدارة العامة للشكاوى والبلاغات والتحري
A4: الدرجة الوظيفية | B4: 2022 | C4: 2023 | D4: 2024 | E4: 2025
A5: فئة خاصة | B5: 19 | C5: 21 | D5: 17 | E5: 19
A6: فئة عليا | B6: 32 | C6: 15 | D6: 52 | E6: 61
A7: فئة أولى | B7: 46 | C7: 34 | D7: 40 | E7: 50
A8: أعضاء السلطة القضائية والنيابة العامة | B8: 18 | C8: 9 | D8: 12 | E8: 16
A9: رؤساء وأعضاء الهيئات المحلية والجمعيات والنقابات | B9: 102 | C9: 89 | D9: 93 | E9: 146
A10: السلك الدبلوماسي والسفارات | B10: 2 | C10: 1 | D10: 2 | E10: 1
A11: منتسبو الأجهزة الأمنية | B11: 0 | C11: 0 | D11: 11 | E11: 18
A12: غير محدد | B12: 0 | C12: 0 | D12: 393 | E12: 476
A13: فئات أخرى | B13: 660 | C13: 418 | D13: 50 | E13: 0
A14: المجموع | B14: 0 | C14: 0 | D14: 0 | E14: 0
A16: ملاحظة: صف 'المجموع' ورد فارغًا في النموذج الأصلي ولم يُحتسب تفاديًا لأي جمع غير موثّق.
I18: 📊 يوضح الرسم البياني أعلاه: 33. توزيع الشكاوى والبلاغات الواردة حسب الدرجة الوظيفية للمشتكى عليه — مقارنة الأرقام عبر الأعوام المتاحة في الجدول المقابل.

Sheet 34-نموذج1 قضايا ومشتبهين
A1: 34. ملخص القضايا والمشتبه بهم لدى نيابة جرائم الفساد (نموذج رقم 1) | G1: ⬆ رجوع للملخص العام
A2: بيانات من نموذج إحصائي رسمي إضافي صادر عن نيابة جرائم الفساد - مصدر مختلف عن شيت 6 (الإدارة العامة للتحقيق بالهيئة)
A4: البيان | B4: 2022 | C4: 2023 | D4: 2024 | E4: 2025
A5: القضايا الواردة - من هيئة مكافحة الفساد | B5: 58 | C5: 35 | D5: 31 | E5: 28
A6: القضايا الواردة - من النائب العام | B6: 29 | C6: 17 | D6: 12 | E6: 13
A7: القضايا الواردة - المجموع | B7: 87 | C7: 52 | D7: 43 | E7: 41
A8: المشتبه بهم المحالون للنيابة - ذكور | B8: 132 | C8: 88 | D8: 80 | E8: 79
A9: المشتبه بهم المحالون للنيابة - إناث | B9: 17 | C9: 9 | D9: 5 | E9: 1
A10: القضايا المنجزة - إحالة لمحكمة جرائم الفساد | B10: 31 | C10: 39 | D10: 35 | E10: 34
A11: القضايا المنجزة - حفظ | B11: 11 | C11: 20 | D11: 18 | E11: 11
A12: القضايا المنجزة - إحالة لجهات أخرى (عدم اختصاص) | B12: 2 | C12: 5 | D12: 3 | E12: 5
A14: ملاحظة: هذا المؤشر مصدره نيابة جرائم الفساد مباشرة (نموذج رقم 1)، وهو مستقل عن شيت "6-الواردة لنيابة جرائم الفساد" الذي مصدره الإدارة العامة للتحقيق بالهيئة. الأرقام هنا مختلفة عن شيت 6 (مثال: القضايا الواردة من النائب العام هنا = 29/17/12/13 مقابل 61/33/38/38 في شيت 6)، لذا أُبقي كل مؤشر في شيته الخاص لتفادي الخلط بين المصدرين.
I18: 📊 يوضح الرسم البياني أعلاه: 34. ملخص القضايا والمشتبه بهم لدى نيابة جرائم الفساد (نموذج رقم 1) — مقارنة الأرقام عبر الأعوام المتاحة في الجدول المقابل.

Sheet 35-نموذج4 حسب نوع الجرم (محكمة)
A1: 35. القضايا المحالة إلى محكمة جرائم الفساد حسب نوع الجرم (نموذج رقم 4) | G1: ⬆ رجوع للملخص العام
A2: يفصل هذا الجدول أنواع جرائم الفساد المشتبه بها في القضايا التي وصلت فعليًا للمحكمة - مصدر مستقل عن شيت 3 (الملفات المحالة للنائب العام)
A4: التكييف القانوني (الجرم) | B4: 2022 | C4: 2023 | D4: 2024 | E4: 2025
A5: التهاون في القيام بالواجبات الوظيفية | B5: 1 | C5: 3 | D5: 5 | E5: 5
A6: الرشوة | B6: 12 | C6: 0 | D6: 0 | E6: 9
A7: الاختلاس | B7: 5 | C7: 4 | D7: 4 | E7: 4
A8: إساءة استعمال السلطة | B8: 10 | C8: 1 | D8: 1 | E8: 33
A9: التزوير والتزييف | B9: 74 | C9: 35 | D9: 12 | E9: 33
A10: قبول الواسطة والمحسوبية والمحاباة | B10: 29 | C10: 1 | D10: 13 | E10: 2
A11: استثمار الوظيفة | B11: 14 | C11: 13 | D11: 10 | E11: 1
A12: إساءة الائتمان | B12: 5 | C12: 16 | D12: 14 | E12: 18
A13: الكسب غير المشروع | B13: 0 | C13: 7 | D13: 0 | E13: 6
A14: عدم الإفصاح عن تضارب المصالح | B14: 4 | C14: 6 | D14: 3 | E14: 3
A15: غسل الأموال الناتجة عن جرائم فساد | B15: 0 | C15: 1 | D15: 2 | E15: 1
A16: المتاجرة بالنفوذ | B16: 0 | C16: 2 | D16: 0 | E16: 4
A17: إعاقة سير العدالة | B17: 0 | C17: 0 | D17: 0 | E17: 6
A18: عدم اختصاص (للغير/القطاع الخاص) | B18: 0 | C18: 0 | D18: 0 | E18: 6 | I18: 📊 يوضح الرسم البياني أعلاه: 35. القضايا المحالة إلى محكمة جرائم الفساد حسب نوع الجرم (نموذج رقم 4) — مقارنة الأرقام عبر الأعوام المتاحة في الجدول المقابل.
A20: ملاحظة: بعض الأرقام في المصدر الأصلي (مثل التزوير في 2022) كانت عبارة عن مجموع قيم فرعية متعددة (7+26+41)، وتم رصد المجموع النهائي فقط لتسهيل التحليل. هذا الجدول يمثل مستوى "القضايا الواصلة فعليًا للمحكمة" وهو مختلف عن شيت "3-المحالة حسب القطاع والجرم" الذي يمثل مستوى "الملفات المحالة للنائب العام" (أرقام الجدولين غير متطابقة لاختلاف المرحلة الإجرائية).

Sheet 36-نموذج3 حسب القطاع (مسجلة)
A1: 36. القضايا المسجلة حسب القطاع (نموذج رقم 3) | G1: ⬆ رجوع للملخص العام
A2: يوضح توزيع قضايا الفساد على القطاعات المختلفة في الدولة - مصدر مستقل عن شيت 20 (الملفات الواردة حسب القطاع)
A4: القطاع | B4: 2022 | C4: 2023 | D4: 2024 | E4: 2025
A5: قطاع عام | B5: 0 | C5: 28 | D5: 23 | E5: 55
A6: هيئات محلية | B6: 0 | C6: 20 | D6: 19 | E6: 13
A7: جمعيات | B7: 0 | C7: 3 | D7: 0 | E7: 4
A8: اتحادات ونقابات | B8: 0 | C8: 0 | D8: 1 | E8: 1
A9: مؤسسات تقوم بخدمة عامة | B9: 0 | C9: 1 | D9: 0 | E9: 0
A10: شركات تساهم عامة فيها الدولة | B10: 0 | C10: 0 | D10: 0 | E10: 0
A11: أخرى | B11: 0 | C11: 1 | D11: 0 | E11: 0
A13: ملاحظة: هذا الجدول لا يتضمن بيانات عام 2022 في المصدر الأصلي (النموذج المرفق بدأ من 2023). هذا المؤشر مستقل عن شيت "20-الواردة حسب القطاع" (الذي مصدره الملفات الواردة للإدارة العامة للتحقيق) وعن شيت "3-المحالة حسب القطاع والجرم" (الذي مصدره الملفات المحالة للنائب العام)؛ الأرقام هنا غير متطابقة معهما لأنها تمثل مستوى إجرائي مختلف (تسجيل القضايا وليس ورودها أو إحالتها).
I18: 📊 يوضح الرسم البياني أعلاه: 36. القضايا المسجلة حسب القطاع (نموذج رقم 3) — مقارنة الأرقام عبر الأعوام المتاحة في الجدول المقابل.

Sheet 11ب-الجهات المكلفة
A1: 11ب. عدد الجهات المكلفة بتقديم إقرارات الذمة المالية | G1: ⬆ رجوع للملخص العام
A2: عدد الجهات (المؤسسات/الدوائر) التي تم تكليفها رسمياً بتعبئة إقرارات الذمة المالية لموظفيها خلال العام
A4: البيان | B4: 2022 | C4: 2023 | D4: 2024 | E4: 2025
A5: عدد الجهات المكلفة | B5: 140 | C5: 130 | D5: 33 | E5: 31
A7: ملاحظة: هذا مؤشر جديد يختلف عن "عدد المكلفين" (الأفراد) الوارد في المؤشر 11، والذي لا يزال غير متوفر.
A8: المصدر: بيانات مزودة من المستخدم استناداً إلى تقارير الهيئة (2022-2025).
A10: عدد الجهات المكلفة (رقمي) | B10: 140 | C10: 130 | D10: 33 | E10: 31
I18: 📊 يوضح الرسم البياني أعلاه: 11ب. عدد الجهات المكلفة بتقديم إقرارات الذمة المالية — مقارنة الأرقام عبر الأعوام المتاحة في الجدول المقابل.

Sheet 12ب-إقرارات دورية
A1: 12ب. عدد الإقرارات الدورية (تجديد كل 5 سنوات) | G1: ⬆ رجوع للملخص العام
A2: إقرارات الذمة المالية المقدمة كتجديد دوري إلزامي كل خمس سنوات، من ضمن إجمالي الإقرارات المستلمة
A4: البيان | B4: 2022 | C4: 2023 | D4: 2024 | E4: 2025
A5: عدد الإقرارات الدورية | B5: 1507 | C5: 1350 | D5: 2057 | E5: 1570
A7: مؤشر جديد لم يكن مدرجاً ضمن القائمة الأصلية.
A8: المصدر: بيانات مزودة من المستخدم استناداً إلى تقارير الهيئة (2022-2025).
I18: 📊 يوضح الرسم البياني أعلاه: 12ب. عدد الإقرارات الدورية (تجديد كل 5 سنوات) — مقارنة الأرقام عبر الأعوام المتاحة في الجدول المقابل.

Sheet 12ج-المجموع التراكمي
A1: 12ج. المجموع التراكمي لإقرارات الذمة المالية المستلمة منذ عام 2012 | G1: ⬆ رجوع للملخص العام
A2: إجمالي عدد الإقرارات المستلمة تراكمياً منذ بدء العمل بالنظام عام 2012 وحتى نهاية كل عام
A4: البيان | B4: 2022 | C4: 2023 | D4: 2024 | E4: 2025
A5: المجموع التراكمي (منذ 2012) | B5: 66951 | C5: 69787 | D5: 72329 | E5: 74411
A6: صافي الزيادة السنوية | C6: =C5-B5 -> 2836 | D6: =D5-C5 -> 2542 | E6: =E5-D5 -> 2082
A7: مؤشر جديد يوضح النمو التراكمي للإقرارات على مدى الزمن. الفارق السنوي = صافي الإقرارات الجديدة المضافة لكل عام.
A8: المصدر: بيانات مزودة من المستخدم استناداً إلى تقارير الهيئة (2022-2025).
I18: 📊 يوضح الرسم البياني أعلاه: 12ج. المجموع التراكمي لإقرارات الذمة المالية المستلمة منذ عام 2012 — مقارنة الأرقام عبر الأعوام المتاحة في الجدول المقابل.

Sheet 12د-التوزيع حسب الفئة
A1: 12د. التوزيع النسبي التراكمي للإقرارات حسب فئة المكلفين (2012-2024) | G1: ⬆ رجوع للملخص العام
A2: وفقاً للتقرير الصادر في 2024، توزيع الإقرارات المستلمة تاريخياً على فئات المكلفين
A4: الفئة | B4: عدد الإقرارات التراكمي | C4: النسبة المئوية
A5: الموظفون المدنيون | B5: 34935 | C5: =B5/72329 -> 0.48300129
A6: منتسبو الأجهزة الأمنية والعسكرية | B6: 20744 | C6: =B6/72329 -> 0.28680059
A7: الهيئات المحلية | B7: 10265 | C7: =B7/72329 -> 0.14192094
A8: مؤسسات منظمة التحرير | B8: 2744 | C8: =B8/72329 -> 0.037937757
A9: الإجمالي (أربع فئات فقط) | B9: =SUM(B5:B8) -> 68688 | C9: =SUM(C5:C8) -> 0.94966058
A10: فئات أخرى/غير محددة (الفارق) | B10: =72329-B9 -> 3641 | C10: =1-C9 -> 0.050339421
A11: المصدر: بيانات مزودة من المستخدم استناداً إلى تقارير الهيئة (2022-2025).
A12: ملاحظة: القاسم المستخدم هو المجموع التراكمي الفعلي حتى 2024 (72,329) كما ورد في التقرير، وليس مجموع الفئات الأربع فقط (68,688)، لتطابق النسب المذكورة في المصدر (48.3%، 28.7%، 14.2%، 3.8%). الفارق (~5.1%) يمثل فئات أخرى لم يتم تفصيلها في المصدر.
A13: المصدر: بيانات مزودة من المستخدم استناداً إلى تقارير الهيئة (2022-2025).
I18: 📊 يوضح الرسم البياني أعلاه: 12د. التوزيع النسبي التراكمي للإقرارات حسب فئة المكلفين (2012-2024) — مقارنة الأرقام عبر الأعوام المتاحة في الجدول المقابل.

Sheet 42-ضبط وإعادة أموال عامة
A1: 42. ضبط وإعادة الأموال العامة (بالشيكل) | G1: ⬆ رجوع للملخص العام
A2: مبالغ مالية تم ضبطها أو استعادتها من جهات خاضعة لقانون مكافحة الفساد أثناء أعمال التحري - مصدر: التقارير السنوية
A4: البيان | B4: 2022 | C4: 2023 | D4: 2024 | E4: 2025
A5: المبالغ المودعة في حساب أمانات الهيئة (شيكل) | B5: 116655 | C5: 55000 | D5: غير متوفر | E5: غير متوفر
A6: المبالغ المعادة إلى الخزينة العامة (شيكل) | B6: 17212 | C6: غير متوفر | D6: غير متوفر | E6: غير متوفر
A7: المبالغ المعادة إلى جهات الصرف (شيكل) | B7: 13925 | C7: 11000 | D7: غير متوفر | E7: غير متوفر
A8: إجمالي المبالغ المضبوطة/المعادة (شيكل) | B8: 147792 | C8: 66000 | D8: غير متوفر | E8: غير متوفر
A10: مؤشر جديد: هذا القسم ("ضبط وإعادة أموال عامة") لم يكن مدرجاً سابقاً في الملف رغم وجوده صراحة في التقريرين السنويين 2022 (ص36) و2023 (ص41). لم يرد هذا القسم إطلاقاً في تقريري 2024 و2025 المرفقين.

Sheet 43-تقارير التدقيق المالي
A1: 43. تقارير التدقيق والتحليل المالي والإداري | G1: ⬆ رجوع للملخص العام
A2: عدد التقارير التدقيقية المعدة من الهيئة والشكاوى/البلاغات المرتبطة بها - مصدر: التقارير السنوية
A4: البيان | B4: 2022 | C4: 2023 | D4: 2024 | E4: 2025
A5: عدد التقارير التدقيقية | B5: 91 | C5: 93 | D5: 51 | E5: 48
A6: عدد الشكاوى والبلاغات المرتبطة | B6: 130 | C6: 115 | D6: 59 | E6: 81
A8: مؤشر جديد لم يكن مدرجاً سابقاً في الملف، رغم توفره في التقارير السنوية الأربعة كافة (2022 ص36، 2023 ص40، 2024 ص54، 2025 ص49-50).

Sheet 44-جهود الرصد التفصيلية
A1: 44. جهود دائرة الرصد (تفصيل مصادر الرصد) | G1: ⬆ رجوع للملخص العام
A2: تفصيل الأخبار والتقارير المرصودة عبر مواقع التواصل الاجتماعي والمصادر المفتوحة والربط البيني - 0 كتفصيل إلا في تقريري 2024 و2025
A4: البيان | B4: 2022 | C4: 2023 | D4: 2024 | E4: 2025
A5: عدد الأخبار المرصودة على مواقع التواصل الاجتماعي والإنترنت | B5: 0 | C5: 0 | D5: 1636 | E5: 1350
A6: عدد تقارير الرصد من مصادر مفتوحة | B6: 0 | C6: 0 | D6: 18 | E6: 29
A7: عدد تقارير الرصد عبر الربط البيني مع المؤسسات العامة | B7: 0 | C7: 0 | D7: 286 | E7: 296
A8: عدد الشكاوى/البلاغات المعتمدة من نتائج الرصد | B8: 14 | C8: 2 | D8: 0 | E8: 0
A10: مؤشر جديد. التفصيل الكامل (أخبار/مصادر مفتوحة/ربط بيني) متوفر فقط في تقريري 2024 (ص55) و2025 (ص50). في تقريري 2022 (ص36) و2023 (ص41) ورد فقط عدد الشكاوى المعتمدة من نتائج الرصد (14 و2 على التوالي) دون تفصيل المصادر.

Sheet 45-بيانات غزة الاستثنائية 2024
A1: 45. بيانات استثنائية خاصة بقطاع غزة (عام 2024 فقط) | G1: ⬆ رجوع للملخص العام
A2: شكاوى وردت من/عن قطاع غزة نتيجة ظروف الحرب - وردت حصراً في التقرير السنوي 2024 (ص52-53) ولا يوجد ما يقابلها في باقي الأعوام
A4: البيان | B4: 2022 | C4: 2023 | D4: 2024 | E4: 2025
A5: شكاوى ضمن اختصاص الهيئة القانوني من المحافظات الجنوبية (غزة) | B5: غير متوفر | C5: غير متوفر | D5: 82 | E5: غير متوفر
A6: شكاوى وردت عبر التطبيقات الإلكترونية من أهالي غزة خارج نطاق اختصاص الهيئة (استغلال المواطنين من قبل تجار وسماسرة) | B6: غير متوفر | C6: غير متوفر | D6: 1070 | E6: غير متوفر
A8: مؤشر جديد جوهري لم يكن مدرجاً في الملف. الشكاوى الـ82 ضمن اختصاص الهيئة تم تأجيل متابعتها بسبب الانقسام وعدم قدرة الهيئة على العمل ميدانياً في قطاع غزة. الشكاوى الـ1,070 (خارج الاختصاص) تتعلق بخمس قضايا رئيسية: (1) استغلال محال الصرافة بعمولات مرتفعة 20%-45%، (2) ارتفاع رسوم السفر غير الرسمية من 350$ إلى 5,000-10,000$، (3) رفع أسعار السلع بشكل مبالغ فيه، (4) تفاوت أسعار السلع بين الدفع النقدي والإلكتروني، (5) حرمان مواطنين من المساعدات لغياب معايير واضحة للتوزيع.

Sheet 46-مؤشرات إضافية متفرقة
A1: 46. مؤشرات إضافية متفرقة (بيانات جزئية غير منتظمة عبر الأعوام) | G1: ⬆ رجوع للملخص العام
A2: مؤشرات وردت بشكل متقطع في تقرير سنوي واحد فقط دون ما يقابلها في باقي الأعوام
A4: البيان | B4: 2022 | C4: 2023 | D4: 2024 | E4: 2025
A5: عدد تقارير الخبرة الفنية (المالية) الصادرة بموجب قرارات رفع السرية المصرفية | B5: غير متوفر | C5: غير متوفر | D5: غير متوفر | E5: 22
